<?xml version="1.0"?>
<robot name="my_mobile_robot_with_hand">
    <link name="base_link">
        <visual>
            <geometry>
                <box size="0.5 0.3 0.23" />
            </geometry>
            <material name="white">
                <color rgba="1.0 1.0 1.0 1.0" />
            </material>
        </visual>
        <collision>
            <geometry>
                <box size="0.5 0.3 0.23" />
            </geometry>
        </collision>
        <inertial>
            <mass value="1.0" />
            <inertia ixx="0.01191" iyy="0.02524" izz="0.02833" ixy="0" iyz="0" ixz="0" />
        </inertial>
    </link>

    <joint name="center_wheel_joint" type="fixed">
        <!-- <axis xyz="0 0 1" /> -->
        <parent link="base_link" />
        <child link="center_wheel" />
        <origin xyz="0.2 0 -0.09" rpy="1.57 0 0" />
    </joint>
    <link name="center_wheel">
        <visual>
            <geometry>
                <cylinder length="0.05" radius="0.05" />
            </geometry>
            <material name="gray">
                <color rgba="0.2 0.2 0.2 1" />
            </material>
        </visual>
        <collision>
            <geometry>
                <cylinder length="0.05" radius="0.05" />
            </geometry>
        </collision>
        <inertial>
            <mass value="0.1" />
            <inertia ixx="0.00008" iyy="0.00008" izz="0.00013" ixy="0" ixz="0" iyz="0" />
        </inertial>
    </link>


    <joint name="left_wheel_joint" type="continuous">
        <axis xyz="0 0 1" />
        <parent link="base_link" />
        <child link="left_wheel" />
        <origin rpy="-1.5708 0 0" xyz="-0.2 0.125 -.09" />
    </joint>
    <link name="left_wheel">
        <visual>
            <geometry>
                <cylinder length="0.05" radius="0.05" />
            </geometry>
            <material name="gray">
                <color rgba="0.2 0.2 0.2 1" />
            </material>
        </visual>
        <collision>
            <geometry>
                <cylinder length="0.05" radius="0.05" />
            </geometry>
        </collision>
        <inertial>
            <mass value="0.1" />
            <inertia ixx="0.00008" iyy="0.00008" izz="0.00013" ixy="0" ixz="0" iyz="0" />
        </inertial>
    </link>
    <joint name="right_wheel_joint" type="continuous">
        <axis xyz="0 0 1" />
        <parent link="base_link" />
        <child link="right_wheel" />
        <origin rpy="-1.5708 0 0" xyz="-0.2 -0.125 -.09" />
    </joint>
    <link name="right_wheel">
        <visual>
            <geometry>
                <cylinder length="0.05" radius="0.035" />
            </geometry>
            <material name="gray">
                <color rgba="0.2 0.2 0.2 1" />
            </material>
        </visual>
        <collision>
            <geometry>
                <cylinder length="0.05" radius="0.035" />
            </geometry>
        </collision>
        <inertial>
            <mass value="0.1" />
            <inertia ixx="0.00005" iyy="0.00005" izz="0.00006" ixy="0" ixz="0" iyz="0" />
        </inertial>
    </link>
    <joint name="scan_joint" type="fixed">
        <axis xyz="0 1 0" />
        <origin xyz="0 0 0.2" rpy="0 0 0" />
        <parent link="base_link" />
        <child link="base_scan" />
    </joint>
    <link name="base_scan">
        <visual>
            <origin xyz="0 0 0" rpy="0 0 0" />
            <geometry>
                <box size="0.1 0.1 0.1" />
            </geometry>
            <material name="red">
                <color rgba="1 0 0 1" />
            </material>
        </visual>
        <collision>
            <origin xyz="0 0 0" rpy="0 0 0" />
            <geometry>
                <box size="0.1 0.1 0.1" />
            </geometry>
        </collision>
        <inertial>
            <mass value="0.1" />
            <origin xyz="0 0 0" rpy="0 0 0" />
            <inertia ixx="0.00017" iyy="0.00017" izz="0.00017" ixy="0" ixz="0" iyz="0" />
        </inertial>
    </link>
    <link name="base_footprint" />
    <joint name="base_joint" type="fixed">
        <origin xyz="0 0 0.126" />
        <parent link="base_footprint" />
        <child link="base_link" />
    </joint>

    <!-- <joint name="fixed_support_link" type="fixed">
        <parent link="base_link" />
        <child link="support_link" />
    </joint>

    <link name="support_link">
        <visual>
            <geometry>
                <box size="0.05 0.05 0.2" />
            </geometry>
            <material name="blue">
                <color rgba="0.0 0.0 1.0 1.0" />
            </material>
            <origin rpy="0 0 0" xyz="0.25 0 -0.08" />
        </visual>
        <collision>
            <geometry>
                <box size="0.05 0.05 0.2" />
            </geometry>
            <origin rpy="0 0 0" xyz="0.25 0 -0.08" />
        </collision>
    </link> -->

    <joint name="fixed" type="fixed">
        <parent link="base_link" />
        <child link="hand_base_link" />
    </joint>

    <link name="hand_base_link">
        <visual>
            <geometry>
                <box size="0.06 0.5 0.15" />
            </geometry>
            <material name="white">
                <color rgba="1.0 1.0 1.0 1.0" />
            </material>
            <origin rpy="0 0 0" xyz="0.15 0 0" />
        </visual>
        <collision>
            <geometry>
                <box size="0.06 0.5 0.15" />
            </geometry>
            <origin rpy="0 0 0" xyz="0.15 0 0" />
        </collision>
    </link>

    <joint name="joint_right" type="revolute">
        <parent link="base_link" />
        <child link="hand_right" />
        <origin rpy="0 0 0" xyz="0 0.2 0" />
        <axis xyz="0 0 1" />
        <limit lower="-0.4" upper="0.5" effort="0.5293" velocity="6.159937255" />
    </joint>

    <joint name="joint_left" type="revolute">
        <parent link="base_link" />
        <child link="hand_left" />
        <origin rpy="0 0 0" xyz="0 -0.2 0" />
        <axis xyz="0 0 -1" />
        <limit lower="-0.4" upper="0.5" effort="0.5293" velocity="6.159937255" />
    </joint>

    <link name="hand_left">
        <visual>
            <geometry>
                <box size="0.1 0.05 0.3" />
            </geometry>
            <material name="white" />
            <origin rpy="0 1.57 0" xyz="0.3 0 0" />
        </visual>
        <collision>
            <geometry>
                <box size="0.1 0.05 0.3" />
            </geometry>
            <origin rpy="0 1.57 0" xyz="0.3 0 0" />
        </collision>
    </link>

    <link name="hand_right">
        <visual>
            <geometry>
                <box size="0.1 0.05 0.3" />
            </geometry>
            <material name="white" />
            <origin rpy="0 1.57 0" xyz="0.3 0 0" />
        </visual>
        <collision>
            <geometry>
                <box size="0.1 0.05 0.3" />
            </geometry>
            <origin rpy="0 1.57 0" xyz="0.3 0 0" />
        </collision>
    </link>





</robot>